<sdf version='1.7'>
  <model name='hummingbird'>
    <link name='wheelbird/base_link'>
      <inertial>
        <pose>0 0 0 0 -0 0</pose>
        <mass>0.71</mass>
        <inertia>
          <ixx>0.007002</ixx>
          <ixy>0</ixy>
          <ixz>0</ixz>
          <iyy>0.007627</iyy>
          <iyz>0</iyz>
          <izz>0.012627</izz>
        </inertia>
      </inertial>
      <collision name='wheelbird/base_link_fixed_joint_lump__stand_collision'>
        <pose>0 0 0.03 1.5708 -0 0</pose>
        <geometry>
          <cylinder>
            <length>0.5</length>
            <radius>0.01</radius>
          </cylinder>
        </geometry>
        <surface>
          <contact>
            <ode>
              <kp>1e+07</kp>
              <kd>1</kd>
            </ode>
          </contact>
          <friction>
            <ode/>
          </friction>
        </surface>
      </collision>
      <collision name='wheelbird/base_link_inertia_collision_1'>
        <pose>0 0 0 0 -0 0.785398</pose>
        <geometry>
          <box>
            <size>0.1 0.1 0.12</size>
          </box>
        </geometry>
      </collision>
      <visual name='wheelbird/base_link_fixed_joint_lump__stand_visual'>
        <pose>0 0 0.03 1.5708 -0 0</pose>
        <geometry>
          <cylinder>
            <length>0.5</length>
            <radius>0.01</radius>
          </cylinder>
        </geometry>
        <material>
          <script>
            <name>Gazebo/Grey</name>
            <uri>file://media/materials/scripts/gazebo.material</uri>
          </script>
        </material>
      </visual>
      <visual name='wheelbird/base_link_inertia_visual_1'>
        <pose>0 0 0 0 -0 0.785398</pose>
        <geometry>
          <mesh>
            <scale>1 1 1</scale>
            <uri>model://wheelbird/meshes/hummingbird.dae</uri>
          </mesh>
        </geometry>
      </visual>
    </link>
    <joint name='left_wheel' type='revolute'>
      <pose relative_to='wheelbird/base_link'>0 0.25 0.03 0 -0 0</pose>
      <parent>wheelbird/base_link</parent>
      <child>left_wheel_link</child>
      <axis>
        <xyz>0 1 0</xyz>
        <limit>
          <lower>-1e+16</lower>
          <upper>1e+16</upper>
        </limit>
        <dynamics>
          <spring_reference>0</spring_reference>
          <spring_stiffness>0</spring_stiffness>
        </dynamics>
      </axis>
    </joint>
    <link name='left_wheel_link'>
      <pose relative_to='left_wheel'>0 0 0 0 -0 0</pose>
      <inertial>
        <pose>0 0 0 0 -0 0</pose>
        <mass>0.19</mass>
        <inertia>
          <ixx>0.00741</ixx>
          <ixy>0</ixy>
          <ixz>0</ixz>
          <iyy>0.00741</iyy>
          <iyz>0</iyz>
          <izz>0.00439</izz>
        </inertia>
      </inertial>
      <collision name='left_wheel_link_collision'>
        <pose>0 0 0 -1.5708 0 0</pose>
        <geometry>
          <cylinder>
            <length>0.01</length>
            <radius>0.22</radius>
          </cylinder>
        </geometry>
        <surface>
          <contact>
            <ode>
              <kp>1e+06</kp>
              <kd>1</kd>
            </ode>
          </contact>
          <friction>
            <ode/>
          </friction>
        </surface>
      </collision>
      <visual name='left_wheel_link_visual'>
        <pose>0 0 0 -1.5708 0 0</pose>
        <geometry>
          <mesh>
            <scale>1 1 1</scale>
            <uri>model://wheelbird/meshes/wheelbird_wheel.stl</uri>
          </mesh>
        </geometry>
        <material>
          <script>
            <name>Gazebo/Grey</name>
            <uri>file://media/materials/scripts/gazebo.material</uri>
          </script>
        </material>
      </visual>
    </link>
    <joint name='right_wheel' type='revolute'>
      <pose relative_to='wheelbird/base_link'>0 -0.25 0.03 0 -0 0</pose>
      <parent>wheelbird/base_link</parent>
      <child>right_wheel_link</child>
      <axis>
        <xyz>0 1 0</xyz>
        <limit>
          <lower>-1e+16</lower>
          <upper>1e+16</upper>
        </limit>
        <dynamics>
          <spring_reference>0</spring_reference>
          <spring_stiffness>0</spring_stiffness>
        </dynamics>
      </axis>
    </joint>
    <link name='right_wheel_link'>
      <pose relative_to='right_wheel'>0 0 0 0 -0 0</pose>
      <inertial>
        <pose>0 0 0 0 -0 0</pose>
        <mass>0.19</mass>
        <inertia>
          <ixx>0.00741</ixx>
          <ixy>0</ixy>
          <ixz>0</ixz>
          <iyy>0.00741</iyy>
          <iyz>0</iyz>
          <izz>0.00439</izz>
        </inertia>
      </inertial>
      <collision name='right_wheel_link_collision'>
        <pose>0 0 0 1.5708 -0 0</pose>
        <geometry>
          <cylinder>
            <length>0.01</length>
            <radius>0.22</radius>
          </cylinder>
        </geometry>
        <surface>
          <contact>
            <ode>
              <kp>1e+06</kp>
              <kd>1</kd>
            </ode>
          </contact>
          <friction>
            <ode/>
          </friction>
        </surface>
      </collision>
      <visual name='right_wheel_link_visual'>
        <pose>0 0 0 1.5708 -0 0</pose>
        <geometry>
          <mesh>
            <scale>1 1 1</scale>
            <uri>model://wheelbird/meshes/wheelbird_wheel.stl</uri>
          </mesh>
        </geometry>
        <material>
          <script>
            <name>Gazebo/Grey</name>
            <uri>file://media/materials/scripts/gazebo.material</uri>
          </script>
        </material>
      </visual>
    </link>
    <joint name='wheelbird/imu_joint' type='revolute'>
      <pose relative_to='wheelbird/base_link'>0 0 0 0 -0 0</pose>
      <parent>wheelbird/base_link</parent>
      <child>wheelbird/imu_link</child>
      <axis>
        <xyz>1 0 0</xyz>
        <limit>
          <lower>0</lower>
          <upper>0</upper>
          <effort>0</effort>
          <velocity>0</velocity>
        </limit>
        <dynamics>
          <spring_reference>0</spring_reference>
          <spring_stiffness>0</spring_stiffness>
        </dynamics>
      </axis>
    </joint>
    <link name='wheelbird/imu_link'>
      <pose relative_to='wheelbird/imu_joint'>0 0 0 0 -0 0</pose>
      <inertial>
        <pose>0 0 0 0 -0 0</pose>
        <mass>0.015</mass>
        <inertia>
          <ixx>1e-05</ixx>
          <ixy>0</ixy>
          <ixz>0</ixz>
          <iyy>1e-05</iyy>
          <iyz>0</iyz>
          <izz>1e-05</izz>
        </inertia>
      </inertial>
    </link>
    <joint name='wheelbird/imugt_joint' type='revolute'>
      <pose relative_to='wheelbird/base_link'>0 0 0 0 -0 0</pose>
      <parent>wheelbird/base_link</parent>
      <child>wheelbird/imugt_link</child>
      <axis>
        <xyz>1 0 0</xyz>
        <limit>
          <lower>0</lower>
          <upper>0</upper>
          <effort>0</effort>
          <velocity>0</velocity>
        </limit>
        <dynamics>
          <spring_reference>0</spring_reference>
          <spring_stiffness>0</spring_stiffness>
        </dynamics>
      </axis>
    </joint>
    <link name='wheelbird/imugt_link'>
      <pose relative_to='wheelbird/imugt_joint'>0 0 0 0 -0 0</pose>
      <inertial>
        <pose>0 0 0 0 -0 0</pose>
        <mass>1e-05</mass>
        <inertia>
          <ixx>1e-05</ixx>
          <ixy>0</ixy>
          <ixz>0</ixz>
          <iyy>1e-05</iyy>
          <iyz>0</iyz>
          <izz>1e-05</izz>
        </inertia>
      </inertial>
    </link>
    <joint name='wheelbird/odometry_sensorgt_joint' type='revolute'>
      <pose relative_to='wheelbird/base_link'>0 0 0 0 -0 0</pose>
      <parent>wheelbird/base_link</parent>
      <child>wheelbird/odometry_sensorgt_link</child>
      <axis>
        <xyz>1 0 0</xyz>
        <limit>
          <lower>0</lower>
          <upper>0</upper>
          <effort>0</effort>
          <velocity>0</velocity>
        </limit>
        <dynamics>
          <spring_reference>0</spring_reference>
          <spring_stiffness>0</spring_stiffness>
        </dynamics>
      </axis>
    </joint>
    <link name='wheelbird/odometry_sensorgt_link'>
      <pose relative_to='wheelbird/odometry_sensorgt_joint'>0 0 0 0 -0 0</pose>
      <inertial>
        <pose>0 0 0 0 -0 0</pose>
        <mass>1e-05</mass>
        <inertia>
          <ixx>1e-05</ixx>
          <ixy>0</ixy>
          <ixz>0</ixz>
          <iyy>1e-05</iyy>
          <iyz>0</iyz>
          <izz>1e-05</izz>
        </inertia>
      </inertial>
    </link>
    <joint name='wheelbird/rotor_0_joint' type='revolute'>
      <pose relative_to='wheelbird/base_link'>0.120208 -0.120208 0.01 0 -0 0</pose>
      <parent>wheelbird/base_link</parent>
      <child>wheelbird/rotor_0</child>
      <axis>
        <xyz>0 0 1</xyz>
        <limit>
          <lower>-1e+16</lower>
          <upper>1e+16</upper>
        </limit>
        <dynamics>
          <spring_reference>0</spring_reference>
          <spring_stiffness>0</spring_stiffness>
        </dynamics>
      </axis>
    </joint>
    <link name='wheelbird/rotor_0'>
      <pose relative_to='wheelbird/rotor_0_joint'>0 0 0 0 -0 0</pose>
      <inertial>
        <pose>0 0 0 0 -0 0</pose>
        <mass>0.009</mass>
        <inertia>
          <ixx>1.755e-06</ixx>
          <ixy>0</ixy>
          <ixz>0</ixz>
          <iyy>7.50675e-05</iyy>
          <iyz>0</iyz>
          <izz>7.66875e-05</izz>
        </inertia>
      </inertial>
      <collision name='wheelbird/rotor_0_collision'>
        <pose>0 0 0 0 -0 0</pose>
        <geometry>
          <cylinder>
            <length>0.005</length>
            <radius>0.1</radius>
          </cylinder>
        </geometry>
        <surface>
          <contact>
            <ode/>
          </contact>
          <friction>
            <ode/>
          </friction>
        </surface>
      </collision>
      <visual name='wheelbird/rotor_0_visual'>
        <pose>0 0 0 0 -0 0</pose>
        <geometry>
          <mesh>
            <scale>0.1 0.1 0.1</scale>
            <uri>model://wheelbird/meshes/propeller_ccw.dae</uri>
          </mesh>
        </geometry>
        <material>
          <script>
            <name>Gazebo/Red</name>
            <uri>file://media/materials/scripts/gazebo.material</uri>
          </script>
        </material>
      </visual>
    </link>
    <joint name='wheelbird/rotor_1_joint' type='revolute'>
      <pose relative_to='wheelbird/base_link'>-0.120208 -0.120208 0.01 0 -0 0</pose>
      <parent>wheelbird/base_link</parent>
      <child>wheelbird/rotor_1</child>
      <axis>
        <xyz>0 0 1</xyz>
        <limit>
          <lower>-1e+16</lower>
          <upper>1e+16</upper>
        </limit>
        <dynamics>
          <spring_reference>0</spring_reference>
          <spring_stiffness>0</spring_stiffness>
        </dynamics>
      </axis>
    </joint>
    <link name='wheelbird/rotor_1'>
      <pose relative_to='wheelbird/rotor_1_joint'>0 0 0 0 -0 0</pose>
      <inertial>
        <pose>0 0 0 0 -0 0</pose>
        <mass>0.009</mass>
        <inertia>
          <ixx>1.755e-06</ixx>
          <ixy>0</ixy>
          <ixz>0</ixz>
          <iyy>7.50675e-05</iyy>
          <iyz>0</iyz>
          <izz>7.66875e-05</izz>
        </inertia>
      </inertial>
      <collision name='wheelbird/rotor_1_collision'>
        <pose>0 0 0 0 -0 0</pose>
        <geometry>
          <cylinder>
            <length>0.005</length>
            <radius>0.1</radius>
          </cylinder>
        </geometry>
        <surface>
          <contact>
            <ode/>
          </contact>
          <friction>
            <ode/>
          </friction>
        </surface>
      </collision>
      <visual name='wheelbird/rotor_1_visual'>
        <pose>0 0 0 0 -0 0</pose>
        <geometry>
          <mesh>
            <scale>0.1 0.1 0.1</scale>
            <uri>model://wheelbird/meshes/propeller_cw.dae</uri>
          </mesh>
        </geometry>
        <material>
          <script>
            <name>Gazebo/Blue</name>
            <uri>file://media/materials/scripts/gazebo.material</uri>
          </script>
        </material>
      </visual>
    </link>
    <joint name='wheelbird/rotor_2_joint' type='revolute'>
      <pose relative_to='wheelbird/base_link'>-0.120208 0.120208 0.01 0 -0 0</pose>
      <parent>wheelbird/base_link</parent>
      <child>wheelbird/rotor_2</child>
      <axis>
        <xyz>0 0 1</xyz>
        <limit>
          <lower>-1e+16</lower>
          <upper>1e+16</upper>
        </limit>
        <dynamics>
          <spring_reference>0</spring_reference>
          <spring_stiffness>0</spring_stiffness>
        </dynamics>
      </axis>
    </joint>
    <link name='wheelbird/rotor_2'>
      <pose relative_to='wheelbird/rotor_2_joint'>0 0 0 0 -0 0</pose>
      <inertial>
        <pose>0 0 0 0 -0 0</pose>
        <mass>0.009</mass>
        <inertia>
          <ixx>1.755e-06</ixx>
          <ixy>0</ixy>
          <ixz>0</ixz>
          <iyy>7.50675e-05</iyy>
          <iyz>0</iyz>
          <izz>7.66875e-05</izz>
        </inertia>
      </inertial>
      <collision name='wheelbird/rotor_2_collision'>
        <pose>0 0 0 0 -0 0</pose>
        <geometry>
          <cylinder>
            <length>0.005</length>
            <radius>0.1</radius>
          </cylinder>
        </geometry>
        <surface>
          <contact>
            <ode/>
          </contact>
          <friction>
            <ode/>
          </friction>
        </surface>
      </collision>
      <visual name='wheelbird/rotor_2_visual'>
        <pose>0 0 0 0 -0 0</pose>
        <geometry>
          <mesh>
            <scale>0.1 0.1 0.1</scale>
            <uri>model://wheelbird/meshes/propeller_ccw.dae</uri>
          </mesh>
        </geometry>
        <material>
          <script>
            <name>Gazebo/Blue</name>
            <uri>file://media/materials/scripts/gazebo.material</uri>
          </script>
        </material>
      </visual>
    </link>
    <joint name='wheelbird/rotor_3_joint' type='revolute'>
      <pose relative_to='wheelbird/base_link'>0.120208 0.120208 0.01 0 -0 0</pose>
      <parent>wheelbird/base_link</parent>
      <child>wheelbird/rotor_3</child>
      <axis>
        <xyz>0 0 1</xyz>
        <limit>
          <lower>-1e+16</lower>
          <upper>1e+16</upper>
        </limit>
        <dynamics>
          <spring_reference>0</spring_reference>
          <spring_stiffness>0</spring_stiffness>
        </dynamics>
      </axis>
    </joint>
    <link name='wheelbird/rotor_3'>
      <pose relative_to='wheelbird/rotor_3_joint'>0 0 0 0 -0 0</pose>
      <inertial>
        <pose>0 0 0 0 -0 0</pose>
        <mass>0.009</mass>
        <inertia>
          <ixx>1.755e-06</ixx>
          <ixy>0</ixy>
          <ixz>0</ixz>
          <iyy>7.50675e-05</iyy>
          <iyz>0</iyz>
          <izz>7.66875e-05</izz>
        </inertia>
      </inertial>
      <collision name='wheelbird/rotor_3_collision'>
        <pose>0 0 0 0 -0 0</pose>
        <geometry>
          <cylinder>
            <length>0.005</length>
            <radius>0.1</radius>
          </cylinder>
        </geometry>
        <surface>
          <contact>
            <ode/>
          </contact>
          <friction>
            <ode/>
          </friction>
        </surface>
      </collision>
      <visual name='wheelbird/rotor_3_visual'>
        <pose>0 0 0 0 -0 0</pose>
        <geometry>
          <mesh>
            <scale>0.1 0.1 0.1</scale>
            <uri>model://wheelbird/meshes/propeller_cw.dae</uri>
          </mesh>
        </geometry>
        <material>
          <script>
            <name>Gazebo/Red</name>
            <uri>file://media/materials/scripts/gazebo.material</uri>
          </script>
        </material>
      </visual>
    </link>
    <plugin name='multirotor_base_plugin' filename='librotors_gazebo_multirotor_base_plugin.so'>
      <robotNamespace>wheelbird</robotNamespace>
      <linkName>wheelbird/base_link</linkName>
      <rotorVelocitySlowdownSim>10</rotorVelocitySlowdownSim>
    </plugin>
    <plugin name='wheelbird_front-right_motor_model' filename='librotors_gazebo_motor_model.so'>
      <robotNamespace>wheelbird</robotNamespace>
      <jointName>wheelbird/rotor_0_joint</jointName>
      <linkName>wheelbird/rotor_0</linkName>
      <turningDirection>ccw</turningDirection>
      <timeConstantUp>0.0125</timeConstantUp>
      <timeConstantDown>0.025</timeConstantDown>
      <maxRotVelocity>838</maxRotVelocity>
      <motorConstant>8.54858e-06</motorConstant>
      <momentConstant>0.016</momentConstant>
      <commandSubTopic>command/motor_speed</commandSubTopic>
      <motorNumber>0</motorNumber>
      <rotorDragCoefficient>8.06428e-05</rotorDragCoefficient>
      <rollingMomentCoefficient>1e-06</rollingMomentCoefficient>
      <motorSpeedPubTopic>motor_speed/0</motorSpeedPubTopic>
      <rotorVelocitySlowdownSim>10</rotorVelocitySlowdownSim>
    </plugin>
    <plugin name='wheelbird_back-right_motor_model' filename='librotors_gazebo_motor_model.so'>
      <robotNamespace>wheelbird</robotNamespace>
      <jointName>wheelbird/rotor_1_joint</jointName>
      <linkName>wheelbird/rotor_1</linkName>
      <turningDirection>cw</turningDirection>
      <timeConstantUp>0.0125</timeConstantUp>
      <timeConstantDown>0.025</timeConstantDown>
      <maxRotVelocity>838</maxRotVelocity>
      <motorConstant>8.54858e-06</motorConstant>
      <momentConstant>0.016</momentConstant>
      <commandSubTopic>command/motor_speed</commandSubTopic>
      <motorNumber>1</motorNumber>
      <rotorDragCoefficient>8.06428e-05</rotorDragCoefficient>
      <rollingMomentCoefficient>1e-06</rollingMomentCoefficient>
      <motorSpeedPubTopic>motor_speed/1</motorSpeedPubTopic>
      <rotorVelocitySlowdownSim>10</rotorVelocitySlowdownSim>
    </plugin>
    <plugin name='wheelbird_back-left_motor_model' filename='librotors_gazebo_motor_model.so'>
      <robotNamespace>wheelbird</robotNamespace>
      <jointName>wheelbird/rotor_2_joint</jointName>
      <linkName>wheelbird/rotor_2</linkName>
      <turningDirection>ccw</turningDirection>
      <timeConstantUp>0.0125</timeConstantUp>
      <timeConstantDown>0.025</timeConstantDown>
      <maxRotVelocity>838</maxRotVelocity>
      <motorConstant>8.54858e-06</motorConstant>
      <momentConstant>0.016</momentConstant>
      <commandSubTopic>command/motor_speed</commandSubTopic>
      <motorNumber>2</motorNumber>
      <rotorDragCoefficient>8.06428e-05</rotorDragCoefficient>
      <rollingMomentCoefficient>1e-06</rollingMomentCoefficient>
      <motorSpeedPubTopic>motor_speed/2</motorSpeedPubTopic>
      <rotorVelocitySlowdownSim>10</rotorVelocitySlowdownSim>
    </plugin>
    <plugin name='wheelbird_front-left_motor_model' filename='librotors_gazebo_motor_model.so'>
      <robotNamespace>wheelbird</robotNamespace>
      <jointName>wheelbird/rotor_3_joint</jointName>
      <linkName>wheelbird/rotor_3</linkName>
      <turningDirection>cw</turningDirection>
      <timeConstantUp>0.0125</timeConstantUp>
      <timeConstantDown>0.025</timeConstantDown>
      <maxRotVelocity>838</maxRotVelocity>
      <motorConstant>8.54858e-06</motorConstant>
      <momentConstant>0.016</momentConstant>
      <commandSubTopic>command/motor_speed</commandSubTopic>
      <motorNumber>3</motorNumber>
      <rotorDragCoefficient>8.06428e-05</rotorDragCoefficient>
      <rollingMomentCoefficient>1e-06</rollingMomentCoefficient>
      <motorSpeedPubTopic>motor_speed/3</motorSpeedPubTopic>
      <rotorVelocitySlowdownSim>10</rotorVelocitySlowdownSim>
    </plugin>
    <plugin name='controller_interface' filename='librotors_gazebo_controller_interface.so'>
      <robotNamespace>wheelbird</robotNamespace>
      <commandAttitudeThrustSubTopic>command/attitude</commandAttitudeThrustSubTopic>
      <commandRateThrustSubTopic>command/rate</commandRateThrustSubTopic>
      <commandMotorSpeedSubTopic>command/motor_speed</commandMotorSpeedSubTopic>
      <imuSubTopic>imu</imuSubTopic>
      <motorSpeedCommandPubTopic>command/motor_speed</motorSpeedCommandPubTopic>
    </plugin>
    <plugin name='mavlink_interface' filename='librotors_gazebo_mavlink_interface.so'>
      <robotNamespace>wheelbird</robotNamespace>
      <mavlinkControlSubTopic>/mavlink/from</mavlinkControlSubTopic>
      <imuSubTopic>imu</imuSubTopic>
      <mavlinkHilSensorPubTopic>/mavlink/to</mavlinkHilSensorPubTopic>
      <motorSpeedsPubTopic>command/motor_speed</motorSpeedsPubTopic>
      <gpsUpdateFreq>5.0</gpsUpdateFreq>
      <rotorCount>4</rotorCount>
      <referenceMagNorth>0.21475</referenceMagNorth>
      <referenceMagEast>0.00797</referenceMagEast>
      <referenceMagDown>0.42817</referenceMagDown>
      <referenceLatitude>47.3667</referenceLatitude>
      <referenceLongitude>8.55</referenceLongitude>
      <referenceAltitude>500.0</referenceAltitude>
    </plugin>
    <plugin name='rotors_gazebo_imu_plugin' filename='librotors_gazebo_imu_plugin.so'>
      <robotNamespace>wheelbird</robotNamespace>
      <linkName>wheelbird/imu_link</linkName>
      <imuTopic>imu</imuTopic>
      <gyroscopeNoiseDensity>0.0003394</gyroscopeNoiseDensity>
      <gyroscopeRandomWalk>3.8785e-05</gyroscopeRandomWalk>
      <gyroscopeBiasCorrelationTime>1000.0</gyroscopeBiasCorrelationTime>
      <gyroscopeTurnOnBiasSigma>0.0087</gyroscopeTurnOnBiasSigma>
      <accelerometerNoiseDensity>0.004</accelerometerNoiseDensity>
      <accelerometerRandomWalk>0.006</accelerometerRandomWalk>
      <accelerometerBiasCorrelationTime>300.0</accelerometerBiasCorrelationTime>
      <accelerometerTurnOnBiasSigma>0.196</accelerometerTurnOnBiasSigma>
    </plugin>
    <plugin name='rotors_gazebo_imugt_plugin' filename='librotors_gazebo_imu_plugin.so'>
      <robotNamespace>wheelbird</robotNamespace>
      <linkName>wheelbird/imugt_link</linkName>
      <imuTopic>ground_truth/imu</imuTopic>
      <gyroscopeNoiseDensity>0.0</gyroscopeNoiseDensity>
      <gyroscopeRandomWalk>0.0</gyroscopeRandomWalk>
      <gyroscopeBiasCorrelationTime>1000.0</gyroscopeBiasCorrelationTime>
      <gyroscopeTurnOnBiasSigma>0.0</gyroscopeTurnOnBiasSigma>
      <accelerometerNoiseDensity>0.0</accelerometerNoiseDensity>
      <accelerometerRandomWalk>0.0</accelerometerRandomWalk>
      <accelerometerBiasCorrelationTime>300.0</accelerometerBiasCorrelationTime>
      <accelerometerTurnOnBiasSigma>0.0</accelerometerTurnOnBiasSigma>
    </plugin>
    <plugin name='odometry_sensorgt' filename='librotors_gazebo_odometry_plugin.so'>
      <linkName>wheelbird/odometry_sensorgt_link</linkName>
      <robotNamespace>wheelbird</robotNamespace>
      <poseTopic>ground_truth/pose</poseTopic>
      <poseWithCovarianceTopic>ground_truth/pose_with_covariance</poseWithCovarianceTopic>
      <positionTopic>ground_truth/position</positionTopic>
      <transformTopic>ground_truth/transform</transformTopic>
      <odometryTopic>ground_truth/odometry</odometryTopic>
      <parentFrameId>world</parentFrameId>
      <childFrameId>wheelbird/base_link</childFrameId>
      <measurementDivisor>1</measurementDivisor>
      <measurementDelay>0</measurementDelay>
      <unknownDelay>0.0</unknownDelay>
      <noiseNormalPosition>0 0 0</noiseNormalPosition>
      <noiseNormalQuaternion>0 0 0</noiseNormalQuaternion>
      <noiseNormalLinearVelocity>0 0 0</noiseNormalLinearVelocity>
      <noiseNormalAngularVelocity>0 0 0</noiseNormalAngularVelocity>
      <noiseUniformPosition>0 0 0</noiseUniformPosition>
      <noiseUniformQuaternion>0 0 0</noiseUniformQuaternion>
      <noiseUniformLinearVelocity>0 0 0</noiseUniformLinearVelocity>
      <noiseUniformAngularVelocity>0 0 0</noiseUniformAngularVelocity>
    </plugin>
    <frame name='wheel_stand' attached_to='wheelbird/base_link'>
      <pose>0 0 0 0 -0 0</pose>
    </frame>
    <frame name='stand' attached_to='wheel_stand'/>
    <frame name='wheelbird/base_joint' attached_to='wheelbird/base_link'>
      <pose>0 0 0 0 -0 0</pose>
    </frame>
    <frame name='wheelbird/base_link_inertia' attached_to='wheelbird/base_joint'/>
  </model>
</sdf>
